<?xml version="1.0" encoding="utf-8"?>
<!-- This URDF was automatically created by SolidWorks to URDF Exporter! Originally created by Stephen Brawner (brawner@gmail.com) 
     Commit Version: 1.6.0-4-g7f85cfe  Build Version: 1.6.7995.38578
     For more information, please see http://wiki.ros.org/sw_urdf_exporter -->
<robot
  name="robot_arm">
  <link
    name="base_link">
    <inertial>
      <origin
        xyz="0.0255730958520303 0.013884602527498 -3.57728338697066E-08"
        rpy="0 0 0" />
      <mass
        value="0.436656281721509" />
      <inertia
        ixx="0.000275493469666201"
        ixy="4.20948592024223E-06"
        ixz="2.42104668670834E-10"
        iyy="0.000797952591500023"
        iyz="-3.55525800160377E-11"
        izz="0.000596315822730298" />
    </inertial>
    <visual>
      <origin
        xyz="0 0 0"
        rpy="0 0 0" />
      <geometry>
        <mesh
          filename="package://robot_arm/meshes/base_link.STL" />
      </geometry>
      <material
        name="">
        <color
          rgba="0.792156862745098 0.819607843137255 0.933333333333333 1" />
      </material>
    </visual>
    <collision>
      <origin
        xyz="0 0 0"
        rpy="0 0 0" />
      <geometry>
        <mesh
          filename="package://robot_arm/meshes/base_link.STL" />
      </geometry>
    </collision>
  </link>
  <link
    name="link1">
    <inertial>
      <origin
        xyz="0.00637793798209238 0.0488798575567449 -0.00229432415669968"
        rpy="0 0 0" />
      <mass
        value="0.356326079956351" />
      <inertia
        ixx="0.000175906216394001"
        ixy="2.23781390290641E-05"
        ixz="5.37299514044409E-05"
        iyy="0.000323052024269637"
        iyz="4.53381729517857E-06"
        izz="0.000370588074351588" />
    </inertial>
    <visual>
      <origin
        xyz="0 0 0"
        rpy="0 0 0" />
      <geometry>
        <mesh
          filename="package://robot_arm/meshes/link1.STL" />
      </geometry>
      <material
        name="">
        <color
          rgba="0.792156862745098 0.819607843137255 0.933333333333333 1" />
      </material>
    </visual>
    <collision>
      <origin
        xyz="0 0 0"
        rpy="0 0 0" />
      <geometry>
        <mesh
          filename="package://robot_arm/meshes/link1.STL" />
      </geometry>
    </collision>
  </link>
  <joint
    name="J1"
    type="continuous">
    <origin
      xyz="0 0 0.054376"
      rpy="1.5708 0 -0.17957" />
    <parent
      link="base_link" />
    <child
      link="link1" />
    <axis
      xyz="0 1 0" />
  </joint>
  <link
    name="link2">
    <inertial>
      <origin
        xyz="-0.00194449812486946 0.0658586717870418 -0.0347270366025151"
        rpy="0 0 0" />
      <mass
        value="0.267463974995638" />
      <inertia
        ixx="0.000716839779430708"
        ixy="-3.95964668231812E-05"
        ixz="1.1486069372782E-05"
        iyy="8.27386087802379E-05"
        iyz="1.69450131847882E-05"
        izz="0.000774379823273382" />
    </inertial>
    <visual>
      <origin
        xyz="0 0 0"
        rpy="0 0 0" />
      <geometry>
        <mesh
          filename="package://robot_arm/meshes/link2.STL" />
      </geometry>
      <material
        name="">
        <color
          rgba="0.792156862745098 0.819607843137255 0.933333333333333 1" />
      </material>
    </visual>
    <collision>
      <origin
        xyz="0 0 0"
        rpy="0 0 0" />
      <geometry>
        <mesh
          filename="package://robot_arm/meshes/link2.STL" />
      </geometry>
    </collision>
  </link>
  <joint
    name="J2"
    type="continuous">
    <origin
      xyz="-0.038353 0.0583 -0.0013209"
      rpy="0.011484 -0.0003636 0.063304" />
    <parent
      link="link1" />
    <child
      link="link2" />
    <axis
      xyz="0.1786 0 0.98392" />
  </joint>
  <link
    name="link3">
    <inertial>
      <origin
        xyz="0.0130563478238648 0.00105076957686734 0.00197573396878195"
        rpy="0 0 0" />
      <mass
        value="0.222311320377135" />
      <inertia
        ixx="9.15294723513774E-05"
        ixy="-2.93868065975677E-06"
        ixz="5.36688667027628E-06"
        iyy="0.00012003016865184"
        iyz="-5.9276568583241E-06"
        izz="0.000140784486113707" />
    </inertial>
    <visual>
      <origin
        xyz="0 0 0"
        rpy="0 0 0" />
      <geometry>
        <mesh
          filename="package://robot_arm/meshes/link3.STL" />
      </geometry>
      <material
        name="">
        <color
          rgba="0.792156862745098 0.819607843137255 0.933333333333333 1" />
      </material>
    </visual>
    <collision>
      <origin
        xyz="0 0 0"
        rpy="0 0 0" />
      <geometry>
        <mesh
          filename="package://robot_arm/meshes/link3.STL" />
      </geometry>
    </collision>
  </link>
  <joint
    name="J3"
    type="continuous">
    <origin
      xyz="0.010122 0.15967 -0.0018373"
      rpy="-0.034158 -0.0032425 -0.18927" />
    <parent
      link="link2" />
    <child
      link="link3" />
    <axis
      xyz="0.1786 0 0.98392" />
  </joint>
  <link
    name="link4">
    <inertial>
      <origin
        xyz="0.00802792604442938 0.00104408266558736 -0.00105833882848586"
        rpy="0 0 0" />
      <mass
        value="0.1696257012172" />
      <inertia
        ixx="5.17820793133401E-05"
        ixy="-6.63726230268937E-06"
        ixz="8.9003241534384E-06"
        iyy="0.000101876628194636"
        iyz="1.17168186802824E-06"
        izz="9.3966015439911E-05" />
    </inertial>
    <visual>
      <origin
        xyz="0 0 0"
        rpy="0 0 0" />
      <geometry>
        <mesh
          filename="package://robot_arm/meshes/link4.STL" />
      </geometry>
      <material
        name="">
        <color
          rgba="0.792156862745098 0.819607843137255 0.933333333333333 1" />
      </material>
    </visual>
    <collision>
      <origin
        xyz="0 0 0"
        rpy="0 0 0" />
      <geometry>
        <mesh
          filename="package://robot_arm/meshes/link4.STL" />
      </geometry>
    </collision>
  </link>
  <joint
    name="J4"
    type="continuous">
    <origin
      xyz="-3.6363E-05 0.014877 0.010525"
      rpy="0.019243 0.0025524 -0.0034694" />
    <parent
      link="link3" />
    <child
      link="link4" />
    <axis
      xyz="0.97586 0.12771 -0.17714" />
  </joint>
  <link
    name="link5">
    <inertial>
      <origin
        xyz="0.00207136926136326 0.00132324610517892 -0.000396911101236221"
        rpy="0 0 0" />
      <mass
        value="0.0179895273320859" />
      <inertia
        ixx="2.01072029683863E-06"
        ixy="-3.67044819195393E-07"
        ixz="2.26773043949782E-08"
        iyy="2.36455919952921E-06"
        iyz="6.03479232687029E-08"
        izz="2.09143498833267E-06" />
    </inertial>
    <visual>
      <origin
        xyz="0 0 0"
        rpy="0 0 0" />
      <geometry>
        <mesh
          filename="package://robot_arm/meshes/link5.STL" />
      </geometry>
      <material
        name="">
        <color
          rgba="0.792156862745098 0.819607843137255 0.933333333333333 1" />
      </material>
    </visual>
    <collision>
      <origin
        xyz="0 0 0"
        rpy="0 0 0" />
      <geometry>
        <mesh
          filename="package://robot_arm/meshes/link5.STL" />
      </geometry>
    </collision>
  </link>
  <joint
    name="J5"
    type="continuous">
    <origin
      xyz="-0.13556 -0.017639 0.024605"
      rpy="-3.0186 0.32455 0.71945" />
    <parent
      link="link4" />
    <child
      link="link5" />
    <axis
      xyz="0.17609 0.019561 0.98418" />
  </joint>
</robot>